<?xml version="1.0"?>
<robot name="robot_arm" xmlns:xacro="http://www.ros.org/wiki/xacro">
    <xacro:include filename="$(find robot_description)/urdf/materials.xacro" />

    <!-- WORLD -->
    <link name="world" />

    <!-- STEP 2 - Arm base link -->
    <joint name="fixed_base" type="fixed">
        <parent link="world" />
        <child link="base_link" />
    </joint>

    <link name="base_link">
        <inertial>
            <mass value="2" />
            <origin xyz="0.0 0.0 0.0" />
            <inertia ixx="0.0117" ixy="0.0" ixz="0.0"
                iyy="0.0117" iyz="0.0"
                izz="0.0225"
            />
        </inertial>
        <collision>
            <geometry>
                <cylinder radius="0.15" length="0.05" />
            </geometry>
            <origin xyz="0.0 0.0 0.0" rpy="0.0 0.0 0.0" />
        </collision>
        <visual>
            <geometry>
                <cylinder radius="0.15" length="0.05" />
            </geometry>
            <material name="red" />
            <origin xyz="0.0 0.0 0.0" rpy="0.0 0.0 0.0" />
        </visual>
    </link>
    <!-- STEP 4 - Shoulder -->
    <joint name="shoulder_pan_joint" type="revolute">
        <limit lower="-3.14" upper="3.14" effort="330.0" velocity="3.14" />
        <parent link="base_link" />
        <child link="shoulder_link" />
        <axis xyz="0 0 1" />
        <origin xyz="0.0 0.0 0.05" rpy="0.0 0.0 0.0" />
        <dynamics damping="0.0" friction="0.0" />
    </joint>

    <!-- Shoulder link -->
    <link name="shoulder_link">
        <inertial>
            <mass value="0.5" />
            <origin xyz="0.0 0.0 0.0" rpy="0.0 0.0 0.0" />
            <inertia ixx="0.0014" ixy="0.0" ixz="0.0"
                iyy="0.0014" iyz="0.0"
                izz="0.0025"
            />
        </inertial>
        <collision>
            <geometry>
                <mesh filename="file://$(find robot_description)/meshes/shoulder.dae" />
            </geometry>
            <origin xyz="0.0 0.0 0.0" rpy="0.0 0.0 0.0" />
        </collision>
        <visual>
            <geometry>
                <mesh filename="file://$(find robot_description)/meshes/shoulder.dae" />
            </geometry>
            <material name="orange" />
            <origin xyz="0.0 0.0 0.0" rpy="0.0 0.0 0.0" />
        </visual>
    </link>

    <!-- Shoulder lift joint -->
    <joint name="shoulder_lift_joint" type="revolute">
        <limit lower="-1.5708" upper="1.5708" effort="330.0" velocity="3.14" />
        <parent link="shoulder_link" />
        <child link="upper_arm_link" />
        <axis xyz="0 1 0" />
        <origin xyz="0.0 0.0 0.025" rpy="0.0 0.0 0.0" />
        <dynamics damping="0.0" friction="0.0" />
    </joint>

    <!-- Upper arm link -->
    <link name="upper_arm_link">
        <inertial>
            <mass value="0.3" />
            <origin xyz="0.0 0.0 0.1" rpy="0.0 0.0 0.0" />
            <inertia ixx="0.0012" ixy="0.0" ixz="0.0"
                iyy="0.0012" iyz="0.0"
                izz="0.0004"
            />
        </inertial>
        <collision>
            <geometry>
                <mesh filename="file://$(find robot_description)/meshes/upper_arm.dae" />
            </geometry>
            <origin xyz="0.0 0.0 0.1" rpy="0.0 0.0 0.0" />
        </collision>
        <visual>
            <geometry>
                <mesh filename="file://$(find robot_description)/meshes/upper_arm.dae" />
            </geometry>
            <material name="orange" />
            <origin xyz="0.0 0.0 0.1" rpy="0.0 0.0 0.0" />
        </visual>
    </link>
    <!-- STEP 5 - Elbow -->
    <joint name="elbow_joint" type="revolute">
        <limit lower="-2.3562" upper="2.3562" effort="150.0" velocity="3.14" />
        <parent link="upper_arm_link" />
        <child link="forearm_link" />
        <axis xyz="0 1 0" />
        <origin xyz="0.0 0.0 0.2" rpy="0.0 0.0 0.0" />
        <dynamics damping="0.0" friction="0.0" />
    </joint>

    <!-- Forearm link -->
    <link name="forearm_link">
        <inertial>
            <mass value="0.2" />
            <origin xyz="0.0 0.0 0.125" rpy="0.0 0.0 0.0" />
            <inertia ixx="0.0011" ixy="0.0" ixz="0.0"
                iyy="0.0011" iyz="0.0"
                izz="0.0004"
            />
        </inertial>
        <collision>
            <geometry>
                <mesh filename="file://$(find robot_description)/meshes/forearm.dae" />
            </geometry>
            <origin xyz="0.0 0.0 0.125" rpy="0.0 0.0 0.0" />
        </collision>
        <visual>
            <geometry>
                <mesh filename="file://$(find robot_description)/meshes/forearm.dae" />
            </geometry>
            <material name="orange" />
            <origin xyz="0.0 0.0 0.125" rpy="0.0 0.0 0.0" />
        </visual>
    </link>
    <!-- STEP 6 - Wrist -->
    <joint name="wrist_joint" type="revolute">
        <limit lower="-2.3562" upper="2.3562" effort="54.0" velocity="3.14" />
        <parent link="forearm_link" />
        <child link="wrist_link" />
        <axis xyz="0 1 0" />
        <origin xyz="0.0 0.0 0.25" rpy="0.0 0.0 0.0" />
        <dynamics damping="0.0" friction="0.0" />
    </joint>

    <!-- Wrist link -->
    <link name="wrist_link">
        <inertial>
            <mass value="0.1" />
            <origin xyz="0.0 0.0 0.05" rpy="0.0 0.0 0.0" />
            <inertia ixx="0.00009" ixy="0.0" ixz="0.0"
                iyy="0.00009" iyz="0.0"
                izz="0.00002"
            />
        </inertial>
        <collision>
            <geometry>
                <mesh filename="file://$(find robot_description)/meshes/wrist.dae" />
            </geometry>
            <origin xyz="0.0 0.0 0.05" rpy="0.0 0.0 0.0" />
        </collision>
        <visual>
            <geometry>
                <mesh filename="file://$(find robot_description)/meshes/wrist.dae" />
            </geometry>
            <material name="orange" />
            <origin xyz="0.0 0.0 0.05" rpy="0.0 0.0 0.0" />
        </visual>
    </link>
    <!-- STEP 7 - Gripper -->
    <joint name="gripper_base_joint" type="fixed">
        <parent link="wrist_link" />
        <child link="gripper_base" />
        <origin xyz="0.0 0 0.105" rpy="0.0 0 0" />
    </joint>

    <!-- Gripper base link -->
    <link name="gripper_base">
        <inertial>
            <mass value="0.1" />
            <origin xyz="0.0 0.0 0.0" rpy="0.0 0.0 0.0" />
            <inertia ixx="0.00009" ixy="0.0" ixz="0.0"
                iyy="0.00009" iyz="0.0"
                izz="0.00002"
            />
        </inertial>
        <collision>
            <geometry>
                <box size=".05 .1 .01" />
            </geometry>
            <origin xyz="0.0 0.0 0.0" rpy="0.0 0.0 0.0" />
        </collision>
        <visual>
            <geometry>
                <box size=".05 .1 .01" />
            </geometry>
            <material name="grey" />
            <origin xyz="0.0 0.0 0.0" rpy="0.0 0.0 0.0" />
        </visual>
    </link>

    <!-- Left finger joint -->
    <joint name="left_finger_joint" type="prismatic">
        <limit lower="0" upper="0.04" effort="100.0" velocity="4.0" />
        <parent link="gripper_base" />
        <child link="left_finger" />
        <axis xyz="0 1 0" />
        <origin xyz="0.0 0.01 0.045" />
    </joint>

    <!-- Left finger link -->
    <link name="left_finger">
        <inertial>
            <mass value="0.1" />
            <origin xyz="0.0 0.0 0.0" rpy="0.0 0.0 0.0" />
            <inertia ixx="0.00009" ixy="0.0" ixz="0.0"
                iyy="0.00009" iyz="0.0"
                izz="0.00002"
            />
        </inertial>
        <collision>
            <geometry>
                <box size=".04 .01 .08" />
            </geometry>
            <origin xyz="0.0 0.0 0.0" rpy="0.0 0.0 0.0" />
        </collision>
        <visual>
            <geometry>
                <box size=".04 .01 .08" />
            </geometry>
            <material name="blue" />
            <origin xyz="0.0 0.0 0.0" rpy="0.0 0.0 0.0" />
        </visual>
    </link>

    <gazebo reference="left_finger">
        <kp>1000000.0</kp>
        <kd>100.0</kd>
        <mu1>15</mu1>
        <mu2>15</mu2>
        <fdir1>1 0 0</fdir1>
        <maxVel>1.0</maxVel>
        <minDepth>0.002</minDepth>
    </gazebo>

    <!-- Right finger joint -->
    <joint name="right_finger_joint" type="prismatic">
        <limit lower="0" upper="0.04" effort="100.0" velocity="4.0" />
        <parent link="gripper_base" />
        <child link="right_finger" />
        <axis xyz="0 -1 0" />
        <origin xyz="0.0 -0.01 0.045" />
    </joint>

    <!-- Right finger link -->
    <link name="right_finger">
        <inertial>
            <mass value="0.1" />
            <origin xyz="0.0 0.0 0.0" rpy="0.0 0.0 0.0" />
            <inertia ixx="0.00009" ixy="0.0" ixz="0.0"
                iyy="0.00009" iyz="0.0"
                izz="0.00002"
            />
        </inertial>
        <collision>
            <geometry>
                <box size=".04 .01 .08" />
            </geometry>
            <origin xyz="0.0 0.0 0.0" rpy="0.0 0.0 0.0" />
        </collision>
        <visual>
            <geometry>
                <box size=".04 .01 .08" />
            </geometry>
            <material name="blue" />
            <origin xyz="0.0 0.0 0.0" rpy="0.0 0.0 0.0" />
        </visual>
    </link>

</robot>